Workbook

Sheet Assumptions
A1: MemoryCare — Financial Model v6.0 · 5 years, monthly · incorporates owner & advisory council decisions (Aug 6–7, 2026)
A2: Blue = inputs; black = formulas; yellow = switches. All salaries entered NET; gross-up applied via coefficient.
A4: GENERAL
A5: FX rate, AMD/USD | B5: 365
A6: Working days/month | B6: 26
A7: Turnover tax (regime 1) | B7: 0.1 | G7: ⚠ Legal memorandum — due Aug 13
A8: VAT threshold, AMD/yr | B8: 115000000
A9: VAT (regime 2) | B9: 0.2 | G9: Above the threshold: price includes 20% VAT + 18% profit tax
A10: Profit tax (regime 2) | B10: 0.18
A12: TARIFFS (Express 60,000 — decision Aug 6) | B12: Price AMD | C12: Deep | D12: Light | E12: Mix
A13: Express | B13: 60000 | C13: 1 | D13: 0 | E13: 0.15 | G13: DECISION Aug 6: Express credit toward subscription — 60 days; repeat Express without conversion in the same year = AMD 40,000
A14: Optimal | B14: 180000 | C14: 2 | D14: 4 | E14: 0.55
A15: Maximum | B15: 240000 | C15: 3 | D15: 6 | E15: 0.3 | G15: DECISION Aug 7: Maximum = 3 deep + 6 light (9 visits/yr, was 4+8) — cost optimization, margin ~50%
A16: Blended price, AMD | B16: =SUMPRODUCT(B13:B15,E13:E15) -> 180000
A17: Avg deep visits/client/yr | B17: =SUMPRODUCT(C13:C15,E13:E15) -> 2.15
A18: Avg light visits/client/yr | B18: =SUMPRODUCT(D13:D15,E13:E15) -> 4
A20: CREWS (NET salaries; decision: 3-person deep crew)
A21: Deep crew: driver-tech + 2 techs, NET AMD/mo | B21: 1000000 | G21: 400,000 + 300,000 + 300,000 take-home
A22: Gross-up coefficient (payroll taxes) | B22: 1.35 | G22: ⚠ Exact rate to be confirmed by accountant
A23: Deep crew GROSS, AMD/mo | B23: =B21*B22 -> 1350000
A24: Pilot crew, months 1–2 (Hayk + 2 techs), NET | B24: 600000 | G24: Decision Aug 6: pilot = Hayk + 2 techs; Hayk unsalaried
A25: Pilot crew GROSS | B25: =B24*B22 -> 810000
A26: Light crew NET, AMD/mo | B26: 450000
A27: Light crew GROSS | B27: =B26*B22 -> 607500
A28: Consumables buffer, deep (+40%) | B28: 102200
A29: Consumables buffer, light (+40%) | B29: 30660
A30: Vehicle: lease+fuel per deep crew, AMD/mo | B30: 112500 | G30: ⚠ Assumption; lease agreement — legal task
A32: PRODUCTIVITY (sites/day)
A33: Deep, months 1–5 / from month 6 | B33: 2.5 | C33: 3.5
A34: Light, months 1–5 / from month 6 | B34: 6 | C34: 8
A35: New-crew hiring trigger: utilization | B35: 0.85 | G35: Decision Aug 6: hiring only at ≥85% actual utilization
A37: OVERHEAD, AMD/mo (excl. marketing)
A38: Legal retainer | B38: 200000
A39: Admin/CRM | B39: 54750
A40: Accountant | B40: 55000 | G40: hiring by Aug 20
A41: Claude Max | B41: =120*B5 -> 43800 | G41: on owner's card → migrate to company
A42: Liability insurance (est.) | B42: 25000 | G42: ⚠ estimate; policy before pilot — legal task
A43: Total overhead (excl. marketing) | B43: =SUM(B38:B42) -> 378550
A45: MARKETING — CAC ladder (decision Aug 6)
A46: Months 1–4 (pilot/organic), AMD/mo | B46: 146000
...

Sheet Monthly 5Y
A1: Monthly model, 60 months (cash basis; taxes on Year Summary sheet)
A3: Month | B3: 1 | C3: 2 | D3: 3 | E3: 4 | F3: 5 | G3: 6 | H3: 7 | I3: 8 | J3: 9 | K3: 10 | L3: 11 | M3: 12 | N3: 13 | O3: 14 | P3: 15 | Q3: 16 | R3: 17 | S3: 18 | T3: 19 | U3: 20 | V3: 21 | W3: 22 | X3: 23 | Y3: 24 | Z3: 25 | AA3: 26 | AB3: 27 | AC3: 28 | AD3: 29 | AE3: 30 | AF3: 31 | AG3: 32 | AH3: 33 | AI3: 34 | AJ3: 35 | AK3: 36 | AL3: 37 | AM3: 38 | AN3: 39 | AO3: 40 | AP3: 41 | AQ3: 42 | AR3: 43 | AS3: 44 | AT3: 45 | AU3: 46 | AV3: 47 | AW3: 48 | AX3: 49 | AY3: 50 | AZ3: 51 | BA3: 52 | BB3: 53 | BC3: 54 | BD3: 55 | BE3: 56 | BF3: 57 | BG3: 58 | BH3: 59 | BI3: 60
A5: New sales (clients) | B5: =ROUND(Assumptions!$B$59/12*Assumptions!$B$60,1) -> 4.6 | C5: =ROUND(Assumptions!$B$59/12*Assumptions!$C$60,1) -> 9.2 | D5: =ROUND(Assumptions!$B$59/12*Assumptions!$D$60,1) -> 13.8 | E5: =ROUND(Assumptions!$B$59/12,1) -> 18.3 | F5: =ROUND(Assumptions!$B$59/12,1) -> 18.3 | G5: =ROUND(Assumptions!$B$59/12,1) -> 18.3 | H5: =ROUND(Assumptions!$B$59/12,1) -> 18.3 | I5: =ROUND(Assumptions!$B$59/12,1) -> 18.3 | J5: =ROUND(Assumptions!$B$59/12,1) -> 18.3 | K5: =ROUND(Assumptions!$B$59/12,1) -> 18.3 | L5: =ROUND(Assumptions!$B$59/12,1) -> 18.3 | M5: =ROUND(Assumptions!$B$59/12,1) -> 18.3 | N5: =ROUND(MAX(0,(Assumptions!$C$68-Assumptions!$B$61*Assumptions!$B$68))/12,1) -> 21.6 | O5: =ROUND(MAX(0,(Assumptions!$C$68-Assumptions!$B$61*Assumptions!$B$68))/12,1) -> 21.6 | P5: =ROUND(MAX(0,(Assumptions!$C$68-Assumptions!$B$61*Assumptions!$B$68))/12,1) -> 21.6 | Q5: =ROUND(MAX(0,(Assumptions!$C$68-Assumptions!$B$61*Assumptions!$B$68))/12,1) -> 21.6 | R5: =ROUND(MAX(0,(Assumptions!$C$68-Assumptions!$B$61*Assumptions!$B$68))/12,1) -> 21.6 | S5: =ROUND(MAX(0,(Assumptions!$C$68-Assumptions!$B$61*Assumptions!$B$68))/12,1) -> 21.6 | T5: =ROUND(MAX(0,(Assumptions!$C$68-Assumptions!$B$61*Assumptions!$B$68))/12,1) -> 21.6 | U5: =ROUND(MAX(0,(Assumptions!$C$68-Assumptions!$B$61*Assumptions!$B$68))/12,1) -> 21.6 | ... Y5: =ROUND(MAX(0,(Assumptions!$C$68-Assumptions!$B$61*Assumptions!$B$68))/12,1) -> 21.6 | Z5: =ROUND(MAX(0,(Assumptions!$D$68-Assumptions!$B$61*Assumptions!$C$68))/12,1) -> 37 | AA5: =ROUND(MAX(0,(Assumptions!$D$68-Assumptions!$B$61*Assumptions!$C$68))/12,1) -> 37 | AB5: =ROUND(MAX(0,(Assumptions!$D$68-Assumptions!$B$61*Assumptions!$C$68))/12,1) -> 37 | AC5: =ROUND(MAX(0,(Assumptions!$D$68-Assumptions!$B$61*Assumptions!$C$68))/12,1) -> 37 | AD5: =ROUND(MAX(0,(Assumptions!$D$68-Assumptions!$B$61*Assumptions!$C$68))/12,1) -> 37 | AE5: =ROUND(MAX(0,(Assumptions!$D$68-Assumptions!$B$61*Assumptions!$C$68))/12,1) -> 37 | AF5: =ROUND(MAX(0,(Assumptions!$D$68-Assumptions!$B$61*Assumptions!$C$68))/12,1) -> 37 | AG5: =ROUND(MAX(0,(Assumptions!$D$68-Assumptions!$B$61*Assumptions!$C$68))/12,1) -> 37 | ... AK5: =ROUND(MAX(0,(Assumptions!$D$68-Assumptions!$B$61*Assumptions!$C$68))/12,1) -> 37 | AL5: =ROUND(MAX(0,(Assumptions!$E$68-Assumptions!$B$61*Assumptions!$D$68))/12,1) -> 53.6 | AM5: =ROUND(MAX(0,(Assumptions!$E$68-Assumptions!$B$61*Assumptions!$D$68))/12,1) -> 53.6 | AN5: =ROUND(MAX(0,(Assumptions!$E$68-Assumptions!$B$61*Assumptions!$D$68))/12,1) -> 53.6 | AO5: =ROUND(MAX(0,(Assumptions!$E$68-Assumptions!$B$61*Assumptions!$D$68))/12,1) -> 53.6 | AP5: =ROUND(MAX(0,(Assumptions!$E$68-Assumptions!$B$61*Assumptions!$D$68))/12,1) -> 53.6 | AQ5: =ROUND(MAX(0,(Assumptions!$E$68-Assumptions!$B$61*Assumptions!$D$68))/12,1) -> 53.6 | AR5: =ROUND(MAX(0,(Assumptions!$E$68-Assumptions!$B$61*Assumptions!$D$68))/12,1) -> 53.6 | AS5: =ROUND(MAX(0,(Assumptions!$E$68-Assumptions!$B$61*Assumptions!$D$68))/12,1) -> 53.6 | ... AW5: =ROUND(MAX(0,(Assumptions!$E$68-Assumptions!$B$61*Assumptions!$D$68))/12,1) -> 53.6 | AX5: =ROUND(MAX(0,(Assumptions!$F$68-Assumptions!$B$61*Assumptions!$E$68))/12,1) -> 71.9 | AY5: =ROUND(MAX(0,(Assumptions!$F$68-Assumptions!$B$61*Assumptions!$E$68))/12,1) -> 71.9 | AZ5: =ROUND(MAX(0,(Assumptions!$F$68-Assumptions!$B$61*Assumptions!$E$68))/12,1) -> 71.9 | BA5: =ROUND(MAX(0,(Assumptions!$F$68-Assumptions!$B$61*Assumptions!$E$68))/12,1) -> 71.9 | BB5: =ROUND(MAX(0,(Assumptions!$F$68-Assumptions!$B$61*Assumptions!$E$68))/12,1) -> 71.9 | BC5: =ROUND(MAX(0,(Assumptions!$F$68-Assumptions!$B$61*Assumptions!$E$68))/12,1) -> 71.9 | BD5: =ROUND(MAX(0,(Assumptions!$F$68-Assumptions!$B$61*Assumptions!$E$68))/12,1) -> 71.9 | BE5: =ROUND(MAX(0,(Assumptions!$F$68-Assumptions!$B$61*Assumptions!$E$68))/12,1) -> 71.9 | ... BI5: =ROUND(MAX(0,(Assumptions!$F$68-Assumptions!$B$61*Assumptions!$E$68))/12,1) -> 71.9
A6: Renewals (clients) | B6: 0 | C6: 0 | D6: 0 | E6: 0 | F6: 0 | G6: 0 | H6: 0 | I6: 0 | J6: 0 | K6: 0 | L6: 0 | M6: 0 | N6: =B7*Assumptions!$B$61 -> 3.91 | O6: =C7*Assumptions!$B$61 -> 7.82 | P6: =D7*Assumptions!$B$61 -> 11.73 | Q6: =E7*Assumptions!$B$61 -> 15.555 | R6: =F7*Assumptions!$B$61 -> 15.555 | S6: =G7*Assumptions!$B$61 -> 15.555 | T6: =H7*Assumptions!$B$61 -> 15.555 | U6: =I7*Assumptions!$B$61 -> 15.555 | ... BI6: =AW7*Assumptions!$B$61 -> 95.110314
A7: Payments in month (annual) | B7: =B5+B6 -> 4.6 | C7: =C5+C6 -> 9.2 | D7: =D5+D6 -> 13.8 | E7: =E5+E6 -> 18.3 | F7: =F5+F6 -> 18.3 | G7: =G5+G6 -> 18.3 | H7: =H5+H6 -> 18.3 | I7: =I5+I6 -> 18.3 | ... BI7: =BI5+BI6 -> 167.01031
A8: Active clients | B8: =SUM(B7:B7) -> 4.6 | C8: =SUM(B7:C7) -> 13.8 | D8: =SUM(B7:D7) -> 27.6 | E8: =SUM(B7:E7) -> 45.9 | F8: =SUM(B7:F7) -> 64.2 | G8: =SUM(B7:G7) -> 82.5 | H8: =SUM(B7:H7) -> 100.8 | I8: =SUM(B7:I7) -> 119.1 | J8: =SUM(B7:J7) -> 137.4 | K8: =SUM(B7:K7) -> 155.7 | L8: =SUM(B7:L7) -> 174 | M8: =SUM(B7:M7) -> 192.3 | N8: =SUM(C7:N7) -> 213.21 | O8: =SUM(D7:O7) -> 233.43 | P8: =SUM(E7:P7) -> 252.96 | Q8: =SUM(F7:Q7) -> 271.815 | R8: =SUM(G7:R7) -> 290.67 | S8: =SUM(H7:S7) -> 309.525 | T8: =SUM(I7:T7) -> 328.38 | ... BI8: =SUM(AX7:BI7) -> 1989.873
A10: CASH
A11: Billings (prepayments), AMD | B11: =B7*Assumptions!$B$16 -> 828000 | C11: =C7*Assumptions!$B$16 -> 1656000 | D11: =D7*Assumptions!$B$16 -> 2484000 | E11: =E7*Assumptions!$B$16 -> 3294000 | F11: =F7*Assumptions!$B$16 -> 3294000 | G11: =G7*Assumptions!$B$16 -> 3294000 | H11: =H7*Assumptions!$B$16 -> 3294000 | I11: =I7*Assumptions!$B$16 -> 3294000 | ... BI11: =BI7*Assumptions!$B$16 -> 30061857
A12: Refund reserve, AMD | B12: =B11*Assumptions!$B$63 -> 24840 | C12: =C11*Assumptions!$B$63 -> 49680 | D12: =D11*Assumptions!$B$63 -> 74520 | E12: =E11*Assumptions!$B$63 -> 98820 | F12: =F11*Assumptions!$B$63 -> 98820 | G12: =G11*Assumptions!$B$63 -> 98820 | H12: =H11*Assumptions!$B$63 -> 98820 | I12: =I11*Assumptions!$B$63 -> 98820 | ... BI12: =BI11*Assumptions!$B$63 -> 901855.7
A14: VISITS & CREWS
A15: Demand: deep visits | B15: =B8*Assumptions!$B$17/12 -> 0.82416667 | C15: =C8*Assumptions!$B$17/12 -> 2.4725 | D15: =D8*Assumptions!$B$17/12 -> 4.945 | E15: =E8*Assumptions!$B$17/12 -> 8.22375 | F15: =F8*Assumptions!$B$17/12 -> 11.5025 | G15: =G8*Assumptions!$B$17/12 -> 14.78125 | H15: =H8*Assumptions!$B$17/12 -> 18.06 | I15: =I8*Assumptions!$B$17/12 -> 21.33875 | ... BI15: =BI8*Assumptions!$B$17/12 -> 356.51891
A16: Demand: light visits | B16: =B8*Assumptions!$B$18/12 -> 1.5333333 | C16: =C8*Assumptions!$B$18/12 -> 4.6 | D16: =D8*Assumptions!$B$18/12 -> 9.2 | E16: =E8*Assumptions!$B$18/12 -> 15.3 | F16: =F8*Assumptions!$B$18/12 -> 21.4 | G16: =G8*Assumptions!$B$18/12 -> 27.5 | H16: =H8*Assumptions!$B$18/12 -> 33.6 | I16: =I8*Assumptions!$B$18/12 -> 39.7 | ... BI16: =BI8*Assumptions!$B$18/12 -> 663.291
A17: Deep crews (by demand, min 1) | B17: =MAX(1,ROUNDUP(B15/(Assumptions!$B$33*Assumptions!$B$6*Assumptions!$B$35),0)) -> 1 | C17: =MAX(1,ROUNDUP(C15/(Assumptions!$B$33*Assumptions!$B$6*Assumptions!$B$35),0)) -> 1 | D17: =MAX(1,ROUNDUP(D15/(Assumptions!$B$33*Assumptions!$B$6*Assumptions!$B$35),0)) -> 1 | E17: =MAX(1,ROUNDUP(E15/(Assumptions!$B$33*Assumptions!$B$6*Assumptions!$B$35),0)) -> 1 | F17: =MAX(1,ROUNDUP(F15/(Assumptions!$B$33*Assumptions!$B$6*Assumptions!$B$35),0)) -> 1 | G17: =MAX(1,ROUNDUP(G15/(Assumptions!$C$33*Assumptions!$B$6*Assumptions!$B$35),0)) -> 1 | H17: =MAX(1,ROUNDUP(H15/(Assumptions!$C$33*Assumptions!$B$6*Assumptions!$B$35),0)) -> 1 | I17: =MAX(1,ROUNDUP(I15/(Assumptions!$C$33*Assumptions!$B$6*Assumptions!$B$35),0)) -> 1 | J17: =MAX(1,ROUNDUP(J15/(Assumptions!$C$33*Assumptions!$B$6*Assumptions!$B$35),0)) -> 1 | K17: =MAX(1,ROUNDUP(K15/(Assumptions!$C$33*Assumptions!$B$6*Assumptions!$B$35),0)) -> 1 | L17: =MAX(1,ROUNDUP(L15/(Assumptions!$C$33*Assumptions!$B$6*Assumptions!$B$35),0)) -> 1 | M17: =MAX(1,ROUNDUP(M15/(Assumptions!$C$33*Assumptions!$B$6*Assumptions!$B$35),0)) -> 1 | N17: =MAX(1,ROUNDUP(N15/(Assumptions!$C$33*Assumptions!$B$6*Assumptions!$B$35),0)) -> 1 | ... BI17: =MAX(1,ROUNDUP(BI15/(Assumptions!$C$33*Assumptions!$B$6*Assumptions!$B$35),0)) -> 5
A18: Light crews (by demand) | B18: =IF((B15+B16)<=Assumptions!$B$33*Assumptions!$B$6*B17*Assumptions!$B$35,0,ROUNDUP(B16/(Assumptions!$B$34*Assumptions!$B$6*Assumptions!$B$35),0)) -> 0 | C18: =IF((C15+C16)<=Assumptions!$B$33*Assumptions!$B$6*C17*Assumptions!$B$35,0,ROUNDUP(C16/(Assumptions!$B$34*Assumptions!$B$6*Assumptions!$B$35),0)) -> 0 | D18: =IF((D15+D16)<=Assumptions!$B$33*Assumptions!$B$6*D17*Assumptions!$B$35,0,ROUNDUP(D16/(Assumptions!$B$34*Assumptions!$B$6*Assumptions!$B$35),0)) -> 0 | E18: =IF((E15+E16)<=Assumptions!$B$33*Assumptions!$B$6*E17*Assumptions!$B$35,0,ROUNDUP(E16/(Assumptions!$B$34*Assumptions!$B$6*Assumptions!$B$35),0)) -> 0 | F18: =IF((F15+F16)<=Assumptions!$B$33*Assumptions!$B$6*F17*Assumptions!$B$35,0,ROUNDUP(F16/(Assumptions!$B$34*Assumptions!$B$6*Assumptions!$B$35),0)) -> 0 | G18: =IF((G15+G16)<=Assumptions!$C$33*Assumptions!$B$6*G17*Assumptions!$B$35,0,ROUNDUP(G16/(Assumptions!$C$34*Assumptions!$B$6*Assumptions!$B$35),0)) -> 0 | H18: =IF((H15+H16)<=Assumptions!$C$33*Assumptions!$B$6*H17*Assumptions!$B$35,0,ROUNDUP(H16/(Assumptions!$C$34*Assumptions!$B$6*Assumptions!$B$35),0)) -> 0 | I18: =IF((I15+I16)<=Assumptions!$C$33*Assumptions!$B$6*I17*Assumptions!$B$35,0,ROUNDUP(I16/(Assumptions!$C$34*Assumptions!$B$6*Assumptions!$B$35),0)) -> 0 | J18: =IF((J15+J16)<=Assumptions!$C$33*Assumptions!$B$6*J17*Assumptions!$B$35,0,ROUNDUP(J16/(Assumptions!$C$34*Assumptions!$B$6*Assumptions!$B$35),0)) -> 0 | K18: =IF((K15+K16)<=Assumptions!$C$33*Assumptions!$B$6*K17*Assumptions!$B$35,0,ROUNDUP(K16/(Assumptions!$C$34*Assumptions!$B$6*Assumptions!$B$35),0)) -> 1 | L18: =IF((L15+L16)<=Assumptions!$C$33*Assumptions!$B$6*L17*Assumptions!$B$35,0,ROUNDUP(L16/(Assumptions!$C$34*Assumptions!$B$6*Assumptions!$B$35),0)) -> 1 | M18: =IF((M15+M16)<=Assumptions!$C$33*Assumptions!$B$6*M17*Assumptions!$B$35,0,ROUNDUP(M16/(Assumptions!$C$34*Assumptions!$B$6*Assumptions!$B$35),0)) -> 1 | N18: =IF((N15+N16)<=Assumptions!$C$33*Assumptions!$B$6*N17*Assumptions!$B$35,0,ROUNDUP(N16/(Assumptions!$C$34*Assumptions!$B$6*Assumptions!$B$35),0)) -> 1 | ... BI18: =IF((BI15+BI16)<=Assumptions!$C$33*Assumptions!$B$6*BI17*Assumptions!$B$35,0,ROUNDUP(BI16/(Assumptions!$C$34*Assumptions!$B$6*Assumptions!$B$35),0)) -> 4
A20: COSTS, AMD
A21: Deep crews: gross payroll+buffer+vehicle | B21: =Assumptions!$B$25+Assumptions!$B$28+Assumptions!$B$30 -> 1024700 | C21: =Assumptions!$B$25+Assumptions!$B$28+Assumptions!$B$30 -> 1024700 | D21: =D17*(Assumptions!$B$23+Assumptions!$B$28+Assumptions!$B$30) -> 1564700 | E21: =E17*(Assumptions!$B$23+Assumptions!$B$28+Assumptions!$B$30) -> 1564700 | F21: =F17*(Assumptions!$B$23+Assumptions!$B$28+Assumptions!$B$30) -> 1564700 | G21: =G17*(Assumptions!$B$23+Assumptions!$B$28+Assumptions!$B$30) -> 1564700 | H21: =H17*(Assumptions!$B$23+Assumptions!$B$28+Assumptions!$B$30) -> 1564700 | I21: =I17*(Assumptions!$B$23+Assumptions!$B$28+Assumptions!$B$30) -> 1564700 | J21: =J17*(Assumptions!$B$23+Assumptions!$B$28+Assumptions!$B$30) -> 1564700 | K21: =K17*(Assumptions!$B$23+Assumptions!$B$28+Assumptions!$B$30) -> 1564700 | ... BI21: =BI17*(Assumptions!$B$23+Assumptions!$B$28+Assumptions!$B$30) -> 7823500
A22: Light crews: gross payroll+buffer | B22: =B18*(Assumptions!$B$27+Assumptions!$B$29) -> 0 | C22: =C18*(Assumptions!$B$27+Assumptions!$B$29) -> 0 | D22: =D18*(Assumptions!$B$27+Assumptions!$B$29) -> 0 | E22: =E18*(Assumptions!$B$27+Assumptions!$B$29) -> 0 | F22: =F18*(Assumptions!$B$27+Assumptions!$B$29) -> 0 | G22: =G18*(Assumptions!$B$27+Assumptions!$B$29) -> 0 | H22: =H18*(Assumptions!$B$27+Assumptions!$B$29) -> 0 | I22: =I18*(Assumptions!$B$27+Assumptions!$B$29) -> 0 | ... BI22: =BI18*(Assumptions!$B$27+Assumptions!$B$29) -> 2552640
A23: Marketing (CAC ladder) | B23: =Assumptions!$B$46 -> 146000 | C23: =Assumptions!$B$46 -> 146000 | D23: =Assumptions!$B$46 -> 146000 | E23: =Assumptions!$B$46 -> 146000 | F23: =Assumptions!$B$47 -> 547500 | G23: =Assumptions!$B$47 -> 547500 | H23: =Assumptions!$B$47 -> 547500 | I23: =Assumptions!$B$47 -> 547500 | J23: =Assumptions!$B$47 -> 547500 | K23: =Assumptions!$B$47 -> 547500 | L23: =Assumptions!$B$47 -> 547500 | M23: =Assumptions!$B$47 -> 547500 | N23: =Assumptions!$B$48 -> 1460000 | O23: =Assumptions!$B$48 -> 1460000 | P23: =Assumptions!$B$48 -> 1460000 | Q23: =Assumptions!$B$48 -> 1460000 | R23: =Assumptions!$B$48 -> 1460000 | S23: =Assumptions!$B$48 -> 1460000 | T23: =Assumptions!$B$48 -> 1460000 | U23: =Assumptions!$B$48 -> 1460000 | ... Y23: =Assumptions!$B$48 -> 1460000 | Z23: =Z11*Assumptions!$B$49 -> 1056303 | AA23: =AA11*Assumptions!$B$49 -> 1116126 | AB23: =AB11*Assumptions!$B$49 -> 1175949 | AC23: =AC11*Assumptions!$B$49 -> 1234471.5 | AD23: =AD11*Assumptions!$B$49 -> 1234471.5 | AE23: =AE11*Assumptions!$B$49 -> 1234471.5 | AF23: =AF11*Assumptions!$B$49 -> 1234471.5 | AG23: =AG11*Assumptions!$B$49 -> 1234471.5 | ... BI23: =BI11*Assumptions!$B$49 -> 3006185.7
A24: Overhead (excl. marketing) | B24: =Assumptions!$B$43 -> 378550 | C24: =Assumptions!$B$43 -> 378550 | D24: =Assumptions!$B$43 -> 378550 | E24: =Assumptions!$B$43 -> 378550 | F24: =Assumptions!$B$43 -> 378550 | G24: =Assumptions!$B$43 -> 378550 | H24: =Assumptions!$B$43 -> 378550 | I24: =Assumptions!$B$43 -> 378550 | ... BI24: =Assumptions!$B$43 -> 378550
A25: One-time launch costs | B25: =Assumptions!$B$52+Assumptions!$B$53/2+Assumptions!$B$54/3 -> 1766666.7 | C25: =Assumptions!$B$53/2+Assumptions!$B$54/3 -> 766666.67 | D25: =Assumptions!$B$54/3 -> 166666.67 | E25: 0 | F25: 0 | G25: 0 | H25: 0 | I25: 0 | J25: 0 | K25: 0 | L25: 0 | M25: 0 | N25: 0 | O25: 0 | P25: 0 | Q25: 0 | R25: 0 | S25: 0 | T25: 0 | U25: 0 | V25: 0 | W25: 0 | X25: 0 | Y25: 0 | Z25: 0 | AA25: 0 | AB25: 0 | AC25: 0 | AD25: 0 | AE25: 0 | AF25: 0 | AG25: 0 | AH25: 0 | AI25: 0 | AJ25: 0 | AK25: 0 | AL25: 0 | AM25: 0 | AN25: 0 | AO25: 0 | AP25: 0 | AQ25: 0 | AR25: 0 | AS25: 0 | AT25: 0 | AU25: 0 | AV25: 0 | AW25: 0 | AX25: 0 | AY25: 0 | AZ25: 0 | BA25: 0 | BB25: 0 | BC25: 0 | BD25: 0 | BE25: 0 | BF25: 0 | BG25: 0 | BH25: 0 | BI25: 0
A26: Total pre-tax costs | B26: =SUM(B21:B25)+B12 -> 3340756.7 | C26: =SUM(C21:C25)+C12 -> 2365596.7 | D26: =SUM(D21:D25)+D12 -> 2330436.7 | E26: =SUM(E21:E25)+E12 -> 2188070 | F26: =SUM(F21:F25)+F12 -> 2589570 | G26: =SUM(G21:G25)+G12 -> 2589570 | H26: =SUM(H21:H25)+H12 -> 2589570 | I26: =SUM(I21:I25)+I12 -> 2589570 | ... BI26: =SUM(BI21:BI25)+BI12 -> 14662731
A28: Pre-tax cash flow | B28: =B11-B26 -> -2512756.7 | C28: =C11-C26 -> -709596.67 | D28: =D11-D26 -> 153563.33 | E28: =E11-E26 -> 1105930 | F28: =F11-F26 -> 704430 | G28: =G11-G26 -> 704430 | H28: =H11-H26 -> 704430 | I28: =I11-I26 -> 704430 | ... BI28: =BI11-BI26 -> 15399125
A30: Note: taxes computed on the Year Summary sheet per the year's regime (10% turnover, or VAT+profit). Prepayment recognition (cash vs deferred) — accountant to confirm.

Sheet Year Summary
A1: Annual summary & tax regimes
B3: Year 1 | C3: Year 2 | D3: Year 3 | E3: Year 4 | F3: Year 5
A4: New sales | B4: =SUM('Monthly 5Y'!B5:M5) -> 192.3 | C4: =SUM('Monthly 5Y'!N5:Y5) -> 259.2 | D4: =SUM('Monthly 5Y'!Z5:AK5) -> 444 | E4: =SUM('Monthly 5Y'!AL5:AW5) -> 643.2 | F4: =SUM('Monthly 5Y'!AX5:BI5) -> 862.8
A5: Total payments (annual) | B5: =SUM('Monthly 5Y'!B7:M7) -> 192.3 | C5: =SUM('Monthly 5Y'!N7:Y7) -> 422.655 | D5: =SUM('Monthly 5Y'!Z7:AK7) -> 803.25675 | E5: =SUM('Monthly 5Y'!AL7:AW7) -> 1325.9682 | F5: =SUM('Monthly 5Y'!AX7:BI7) -> 1989.873
A6: Active clients at year end | B6: ='Monthly 5Y'!M8 -> 192.3 | C6: ='Monthly 5Y'!Y8 -> 422.655 | D6: ='Monthly 5Y'!AK8 -> 803.25675 | E6: ='Monthly 5Y'!AW8 -> 1325.9682 | F6: ='Monthly 5Y'!BI8 -> 1989.873
A7: Billings (pre-tax revenue), AMD | B7: =SUM('Monthly 5Y'!B11:M11) -> 34614000 | C7: =SUM('Monthly 5Y'!N11:Y11) -> 76077900 | D7: =SUM('Monthly 5Y'!Z11:AK11) -> 144586215 | E7: =SUM('Monthly 5Y'!AL11:AW11) -> 2.3867428e+08 | F7: =SUM('Monthly 5Y'!AX11:BI11) -> 3.5817714e+08
A8: ⚠ VAT threshold exceeded? | B8: =IF(B7>Assumptions!$B$8,"YES","no") -> no | C8: =IF(C7>Assumptions!$B$8,"YES","no") -> no | D8: =IF(D7>Assumptions!$B$8,"YES","no") -> YES | E8: =IF(E7>Assumptions!$B$8,"YES","no") -> YES | F8: =IF(F7>Assumptions!$B$8,"YES","no") -> YES
A9: Tax regime for the year | B9: =IF(B8="YES","VAT 20% + profit 18%","10% turnover") -> 10% turnover | C9: =IF(C8="YES","VAT 20% + profit 18%","10% turnover") -> 10% turnover | D9: =IF(D8="YES","VAT 20% + profit 18%","10% turnover") -> VAT 20% + profit 18% | E9: =IF(E8="YES","VAT 20% + profit 18%","10% turnover") -> VAT 20% + profit 18% | F9: =IF(F8="YES","VAT 20% + profit 18%","10% turnover") -> VAT 20% + profit 18%
A10: Costs (incl. refund reserve), AMD | B10: =SUM('Monthly 5Y'!B26:M26) -> 32855900 | C10: =SUM('Monthly 5Y'!N26:Y26) -> 50779257 | D10: =SUM('Monthly 5Y'!Z26:AK26) -> 74292968 | E10: =SUM('Monthly 5Y'!AL26:AW26) -> 1.1168242e+08 | F10: =SUM('Monthly 5Y'!AX26:BI26) -> 1.6211377e+08
A11: Taxes for the year, AMD | B11: =IF(B8="YES",B7-B7/(1+Assumptions!$B$9)+MAX(0,(B7/(1+Assumptions!$B$9)-B10))*Assumptions!$B$10,B7*Assumptions!$B$7) -> 3461400 | C11: =IF(C8="YES",C7-C7/(1+Assumptions!$B$9)+MAX(0,(C7/(1+Assumptions!$B$9)-C10))*Assumptions!$B$10,C7*Assumptions!$B$7) -> 7607790 | D11: =IF(D8="YES",D7-D7/(1+Assumptions!$B$9)+MAX(0,(D7/(1+Assumptions!$B$9)-D10))*Assumptions!$B$10,D7*Assumptions!$B$7) -> 32412901 | E11: =IF(E8="YES",E7-E7/(1+Assumptions!$B$9)+MAX(0,(E7/(1+Assumptions!$B$9)-E10))*Assumptions!$B$10,E7*Assumptions!$B$7) -> 55477355 | F11: =IF(F8="YES",F7-F7/(1+Assumptions!$B$9)+MAX(0,(F7/(1+Assumptions!$B$9)-F10))*Assumptions!$B$10,F7*Assumptions!$B$7) -> 84242283 | G11: VAT regime: VAT out of price + 18% on profit (simplified, no input VAT) — accountant to refine
A12: EBITDA (post-tax), AMD | B12: =B7-B10-B11 -> -1703300 | C12: =C7-C10-C11 -> 17690853 | D12: =D7-D10-D11 -> 37880347 | E12: =E7-E10-E11 -> 71514511 | F12: =F7-F10-F11 -> 1.1182109e+08
A13: EBITDA, $ | B13: =B12/Assumptions!$B$5 -> -4666.5753 | C13: =C12/Assumptions!$B$5 -> 48468.09 | D13: =D12/Assumptions!$B$5 -> 103781.77 | E13: =E12/Assumptions!$B$5 -> 195930.17 | F13: =F12/Assumptions!$B$5 -> 306359.15
A15: SAM check: Year-5 active clients vs SAM base | B15: =F6/Assumptions!$C$66 -> 0.1326582 | C15: penetration of SAM base

Sheet Unit Economics
A1: Unit economics (conservative: months 1–5 productivity, full crew)
A3: Deep-visit unit cost, AMD | B3: =(Assumptions!B23+Assumptions!B28+Assumptions!B30)/(Assumptions!B33*Assumptions!B6) -> 24072.308
A4: Light-visit unit cost, AMD | B4: =(Assumptions!B27+Assumptions!B29)/(Assumptions!B34*Assumptions!B6) -> 4090.7692
B6: Express | C6: Optimal | D6: Maximum
A7: Price AMD | B7: =Assumptions!B13 -> 60000 | C7: =Assumptions!B14 -> 180000 | D7: =Assumptions!B15 -> 240000
A8: Tax 10% (regime 1) | B8: =B7*Assumptions!$B$7 -> 6000 | C8: =C7*Assumptions!$B$7 -> 18000 | D8: =D7*Assumptions!$B$7 -> 24000
A9: Visit costs | B9: =Assumptions!C13*$B$3+Assumptions!D13*$B$4 -> 24072.308 | C9: =Assumptions!C14*$B$3+Assumptions!D14*$B$4 -> 64507.692 | D9: =Assumptions!C15*$B$3+Assumptions!D15*$B$4 -> 96761.538
A10: Gross profit, AMD | B10: =B7-B8-B9 -> 29927.692 | C10: =C7-C8-C9 -> 97492.308 | D10: =D7-D8-D9 -> 119238.46
A11: Margin, % of price | B11: =B10/B7 -> 0.49879487 | C11: =C10/C7 -> 0.54162393 | D11: =D10/D7 -> 0.49682692
A12: Price per visit, USD | B12: =B7/Assumptions!$B$5/(Assumptions!C13+Assumptions!D13) -> 164.38356 | C12: =C7/Assumptions!$B$5/(Assumptions!C14+Assumptions!D14) -> 82.191781 | D12: =D7/Assumptions!$B$5/(Assumptions!C15+Assumptions!D15) -> 73.059361
A14: At month-6+ productivity (3.5/8.0) unit costs are ~25–30% lower — this sheet is conservative.

Sheet Funding
A1: Funding requirement (owner tranches as needed)
A3: Cumulative pre-tax cash flow, 60-month minimum, AMD | B3: =MIN(B4:BI4) -> -3222353.3
A4: (service row: cumulative flow) | B4: ='Monthly 5Y'!B28 -> -2512756.7 | C4: =B4+'Monthly 5Y'!C28 -> -3222353.3 | D4: =C4+'Monthly 5Y'!D28 -> -3068790 | E4: =D4+'Monthly 5Y'!E28 -> -1962860 | F4: =E4+'Monthly 5Y'!F28 -> -1258430 | G4: =F4+'Monthly 5Y'!G28 -> -554000 | H4: =G4+'Monthly 5Y'!H28 -> 150430 | I4: =H4+'Monthly 5Y'!I28 -> 854860 | J4: =I4+'Monthly 5Y'!J28 -> 1559290 | ... BI4: =BH4+'Monthly 5Y'!BI28 -> 4.2040523e+08
A6: Peak requirement (incl. ~10% Year-1 tax) | B6: =-B3*1.1 -> 3544588.7
A7: Contingency reserve (28%) | B7: =B6*0.28 -> 992484.83
A8: Incident reserve (decision Aug 6) | B8: 500000
A9: TOTAL requirement, AMD / USD | B9: =B6+B7+B8 -> 5037073.5 | C9: =B9/Assumptions!B5 -> 13800.201
A11: Kill criterion (adopted): <40 paying clients by month 4 post-launch → stop and rebuild the model, not additional funding.
