Workbook

Sheet Assumptions
A1: MEMORY CARE — Assumptions (все синие ячейки — редактируемые входные данные)
A3: FX & ОБЩИЕ
A4: AMD за 1 USD | B4: 365
A5: Рабочих дней в месяце (экипаж) | B5: 26
A6: Налог с оборота | B6: 0.1
A8: НОВАЯ ТАРИФНАЯ СЕТКА (заменяет архивные плоские $500/$650)
A9: Тариф | B9: Цена, AMD | C9: Цена, $ | D9: Тяж. визитов/год | E9: Лёгк. визитов/год | F9: Доля в миксе клиентов
A10: Разовый визит (Экспресс) | B10: 80000 | C10: =B10/FX -> 219.17808 | D10: 1 | E10: 0 | F10: 0.15
A11: Годовой «Оптимальный» (6 визитов) | B11: 180000 | C11: =B11/FX -> 493.15068 | D11: 2 | E11: 4 | F11: 0.55
A12: Годовой «Максимум» (12 визитов) | B12: 240000 | C12: =B12/FX -> 657.53425 | D12: 4 | E12: 8 | F12: 0.3
A13: ИТОГО доля (проверка = 100%) | F13: =SUM(F10:F12) -> 1
A14: Взвешенная (blended) цена подписки | B14: =SUMPRODUCT(B10:B12,F10:F12) -> 183000 | C14: =B14/FX -> 501.36986
A15: Взвешенные тяж. визиты/клиента/год | D15: =SUMPRODUCT(D10:D12,F10:F12) -> 2.45
A16: Взвешенные лёгк. визиты/клиента/год | E16: =SUMPRODUCT(E10:E12,F10:F12) -> 4.6
A17: Именованные ссылки на строки визитов по тарифам (для Unit Economics):
A18: ЗАРПЛАТЫ — ТЯЖЁЛАЯ КОМАНДА (AMD/месяц)
A19: Рабочий (уборщик) | B19: 220000
A20: Водитель / фотоотчётчик | B20: 260000
A21: Работников в команде | B21: 2
A22: Водителей в команде | B22: 1
A24: МИНИ-ВИЗИТЁР — ЛЁГКАЯ КОМАНДА (AMD/месяц)
A25: Базовая зарплата | B25: 220000
A26: Компенсация за личный авто | B26: 100000
A28: ТРАНСПОРТ И ОБОРУДОВАНИЕ (USD)
A29: Ford Transit — цена покупки | B29: 14000
A30: Ford Transit — расход/месяц | B30: 325
A31: Комплект инструмента (тяж., разово) | B31: 2000
A32: Авто мини-визитёра, расход/месяц | B32: 125
A33: Комплект лёгкой уборки (разово) | B33: 250
A34: Запуск / сайт / брендинг (разово, Год1) | B34: 1000
A36: ДНЕВНАЯ ТОЧЕЧНАЯ МОЩНОСТЬ (points/day)
B37: Рассредоточенно | C37: Кластер (Ереван)
A38: Тяжёлый экипаж | B38: 5.5 | C38: 8.5
A39: Мини-визитёр | B39: 9 | C39: 14
A41: НАКЛАДНЫЕ РАСХОДЫ (USD/месяц, база Год1)
A42: Маркетинг, Год1 | B42: 300
A43: Рост маркетинга / год (+ USD/мес) | B43: 100
A44: Админ/бухгалтерия/CRM/страховка, Год1 | B44: 150
A45: Рост админ / год (+ USD/мес) | B45: 50
A47: ОТТОК И РОСТ, ГОД 2–5
...

Sheet Capacity Model
A1: Capacity Model — мощность 1 тяжёлого экипажа + 1 мини-визитёра (новая тарифная сетка)
A3: ГОДОВАЯ СЕБЕСТОИМОСТЬ ЭКИПАЖА (USD)
A4: Тяжёлый экипаж — зарплаты в год | B4: =(WORKER_SAL*N_WORKERS+DRIVER_SAL*N_DRIVERS)*12/FX -> 23013.699
A5: Тяжёлый экипаж — расход авто в год | B5: =VAN_RUN*12 -> 3900
A6: Тяжёлый экипаж — ИТОГО годовая операционная стоимость | B6: =B4+B5 -> 26913.699
A8: Мини-визитёр — зарплата+компенсация в год | B8: =(MINI_SAL+MINI_ALLOW)*12/FX -> 10520.548
A9: Мини-визитёр — расход авто в год | B9: =MINI_RUN*12 -> 1500
A10: Мини-визитёр — ИТОГО годовая операционная стоимость | B10: =B8+B9 -> 12020.548
A12: ГОДОВАЯ ТОЧЕЧНАЯ МОЩНОСТЬ (points/year = points/day x WORKDAYS x 12)
A13: Тяжёлый экипаж — точек/год, рассредоточенно | B13: =FULL_PTS_DISP*WORKDAYS*12 -> 1716
A14: Тяжёлый экипаж — точек/год, кластер | B14: =FULL_PTS_CLUST*WORKDAYS*12 -> 2652
A15: Мини-визитёр — точек/год, рассредоточенно | B15: =MINI_PTS_DISP*WORKDAYS*12 -> 2808
A16: Мини-визитёр — точек/год, кластер | B16: =MINI_PTS_CLUST*WORKDAYS*12 -> 4368
A18: МОЩНОСТЬ В КЛИЕНТАХ (с учётом новой взвешенной интенсивности визитов)
A19: Взвешенные тяж. визиты / клиента / год (из Assumptions) | B19: =BLEND_HVISITS -> 2.45
A20: Взвешенные лёгк. визиты / клиента / год (из Assumptions) | B20: =BLEND_LVISITS -> 4.6
A21: Клиентов на 1 тяжёлый экипаж — рассредоточенно | B21: =B13/B19 -> 700.40816
A22: Клиентов на 1 мини-визитёра — рассредоточенно | B22: =B15/B20 -> 610.43478
A23: СИСТЕМНАЯ МОЩНОСТЬ (1 экипаж + 1 визитёр, рассредоточенно) = MIN(...) | B23: =MIN(B21,B22) -> 610.43478
A25: Вывод: максимум сценария — 300 клиентов (Позитивный).
A26: Даже без кластерного бонуса плотности мощности одного экипажа + одного визитёра хватает на весь Год 1
A27: во всех трёх сценариях — второй экипаж НЕ требуется в Году 1 ни в одном из них.
A28: (Причина: новая тарифная сетка кратно легче по визитной нагрузке, чем архивная плоская — 2.45 тяж. + 4.6 лёгк. визитов/клиента/год против прежних 6+12.)
A30: 5-ЛЕТНИЙ ПЛАН МОЩНОСТИ (справочно, кластеризация с Года1 — единый экипаж в кластере)
B31: Year 1 | C31: Year 2 | D31: Year 3 | E31: Year 4 | F31: Year 5
A32: Тяжёлых экипажей (#) | B32: 1 | C32: 1 | D32: 2 | E32: 2 | F32: 2
A33: Мини-визитёров (#) | B33: 1 | C33: 1 | D33: 2 | E33: 2 | F33: 3
A34: Кластеризация активна? (1/0) | B34: 1 | C34: 1 | D34: 1 | E34: 1 | F34: 1
A35: Мощность по тяж. экипажам (клиентов) | B35: =(B32)*IF(B34=1,B14,B13)/B19 -> 1082.449 | C35: =(C32)*IF(C34=1,B14,B13)/B19 -> 1082.449 | D35: =(D32)*IF(D34=1,B14,B13)/B19 -> 2164.898 | E35: =(E32)*IF(E34=1,B14,B13)/B19 -> 2164.898 | F35: =(F32)*IF(F34=1,B14,B13)/B19 -> 2164.898
A36: Мощность по мини-визитёрам (клиентов) | B36: =(B33)*IF(B34=1,B16,B15)/B20 -> 949.56522 | C36: =(C33)*IF(C34=1,B16,B15)/B20 -> 949.56522 | D36: =(D33)*IF(D34=1,B16,B15)/B20 -> 1899.1304 | E36: =(E33)*IF(E34=1,B16,B15)/B20 -> 1899.1304 | F36: =(F33)*IF(F34=1,B16,B15)/B20 -> 2848.6957
A37: Системная мощность = MIN(...) | B37: =MIN(B35,B36) -> 949.56522 | C37: =MIN(C35,C36) -> 949.56522 | D37: =MIN(D35,D36) -> 1899.1304 | E37: =MIN(E35,E36) -> 1899.1304 | F37: =MIN(F35,F36) -> 2164.898
A39: СПРАВОЧНИК КОНФИГУРАЦИЙ МОЩНОСТИ (используется в 5-Year P&L по сценариям)
A40: Конфигурация | B40: Экипажи | C40: Визитёры | D40: Кластер? | E40: Мощность, клиентов
A41: 1 экипаж + 1 визитёр, рассредоточенно | B41: 1 | C41: 1 | D41: 0 | E41: =MIN(B41*IF(D41=1,B14,B13)/B19,C41*IF(D41=1,B16,B15)/B20) -> 610.43478
A42: 1 экипаж + 2 визитёра, рассредоточенно | B42: 1 | C42: 2 | D42: 0 | E42: =MIN(B42*IF(D42=1,B14,B13)/B19,C42*IF(D42=1,B16,B15)/B20) -> 700.40816
A43: 2 экипажа + 2 визитёра, кластер | B43: 2 | C43: 2 | D43: 1 | E43: =MIN(B43*IF(D43=1,B14,B13)/B19,C43*IF(D43=1,B16,B15)/B20) -> 1899.1304
A45: Разные сценарии упираются в разную конфигурацию мощности только в Позитивном сценарии (Год 4-5) — см. 5-Year P&L.

Sheet Unit Economics
A1: Unit Economics — себестоимость и маржа по тарифным планам (новая сетка)
A3: Стоимость 1 точки (визита), USD — рассредоточенно
A4: Тяжёлый визит (точка) | B4: =FULL_ANNUAL_COST/'Capacity Model'!B13 -> 15.683974
A5: Лёгкий визит (точка) | B5: =MINI_ANNUAL_COST/'Capacity Model'!B15 -> 4.2808219
A7: СЕБЕСТОИМОСТЬ И МАРЖА ПО ТАРИФАМ (прямые затраты, без наклад. расходов — маркетинг/админ считаются на 5-Year P&L)
B8: Разовый (Экспресс) | C8: Оптимальный | D8: Максимум | E8: Blended
A9: Цена подписки, AMD | B9: =PRICE_EXPRESS -> 80000 | C9: =PRICE_OPTIMAL -> 180000 | D9: =PRICE_MAX -> 240000 | E9: =BLEND_PRICE_AMD -> 183000
A10: Выручка после налога с оборота (x(1-TAX_RATE)) | B10: =B9*(1-TAX_RATE) -> 72000 | C10: =C9*(1-TAX_RATE) -> 162000 | D10: =D9*(1-TAX_RATE) -> 216000 | E10: =E9*(1-TAX_RATE) -> 164700
A11: Тяж. визитов/год | B11: =HV_EXPRESS -> 1 | C11: =HV_OPTIMAL -> 2 | D11: =HV_MAX -> 4 | E11: =BLEND_HVISITS -> 2.45
A12: Лёгк. визитов/год | B12: =LV_EXPRESS -> 0 | C12: =LV_OPTIMAL -> 4 | D12: =LV_MAX -> 8 | E12: =BLEND_LVISITS -> 4.6
A13: Прямая себестоимость (visits x cost/point), AMD | B13: =(B11*$B$4+B12*$B$5)*FX -> 5724.6503 | C13: =(C11*$B$4+C12*$B$5)*FX -> 17699.301 | D13: =(D11*$B$4+D12*$B$5)*FX -> 35398.601 | E13: =(E11*$B$4+E12*$B$5)*FX -> 21212.893
A14: Валовая прибыль, AMD | B14: =B10-B13 -> 66275.35 | C14: =C10-C13 -> 144300.7 | D14: =D10-D13 -> 180601.4 | E14: =E10-E13 -> 143487.11
A15: Валовая маржа, % | B15: =B14/B10 -> 0.92049097 | C15: =C14/C10 -> 0.89074506 | D15: =D14/D10 -> 0.83611759 | E15: =E14/E10 -> 0.87120283
A17: Доля в клиентском миксе | B17: =Assumptions!F10 -> 0.15 | C17: =Assumptions!F11 -> 0.55 | D17: =Assumptions!F12 -> 0.3 | E17: =SUM(B17:D17) -> 1
A19: Примечание: прямая себестоимость = визиты x стоимость точки (Capacity Model); не включает маркетинг/админ/капекс —
A20: те считаются на уровне компании в 'Y1 Monthly Build' и '5-Year P&L'.
A21: Маржа выше, чем в исходном текстовом документе Memory Care (v4.0), т.к. Excel-модель изначально считает по более высокой
A22: производительности экипажа (5.5-8.5 точек/день) против 2.5-3.5 точек/день в текстовом плане — это разные допущения, стоит сверить с Давидом.

Sheet Y1 Monthly Build
A1: Y1 Monthly Build — три сценария (плавное помесячное распределение новых клиентов) | B1: Худший — 160 клиентов | L1: Нормальный — 220 клиентов | V1: Позитивный — 300 клиентов
A2: Месяц | B2: Новые клиенты/мес | C2: Клиенты нарастающим итогом | D2: Выручка (cash), AMD | E2: Расходы тяж. экипажа, $ | F2: Расходы мини-визитёра, $ | G2: Маркетинг+админ, $ | H2: Капекс, $ | I2: Чистый ден. поток, $ | J2: Накопленный кэш, $ | L2: Новые клиенты/мес | M2: Клиенты нарастающим итогом | N2: Выручка (cash), AMD | O2: Расходы тяж. экипажа, $ | P2: Расходы мини-визитёра, $ | Q2: Маркетинг+админ, $ | R2: Капекс, $ | S2: Чистый ден. поток, $ | T2: Накопленный кэш, $ | V2: Новые клиенты/мес | W2: Клиенты нарастающим итогом | X2: Выручка (cash), AMD | Y2: Расходы тяж. экипажа, $ | Z2: Расходы мини-визитёра, $ | AA2: Маркетинг+админ, $ | AB2: Капекс, $ | AC2: Чистый ден. поток, $ | AD2: Накопленный кэш, $
A3: 1 | B3: 5 | C3: =B3 -> 5 | D3: =B3*BLEND_PRICE_AMD -> 915000 | E3: =FULL_ANNUAL_COST/12 -> 2242.8082 | F3: =IF(1>=MINI_HIRE_MONTH,MINI_ANNUAL_COST/12,0) -> 0 | G3: =MKT_Y1+ADMIN_Y1 -> 450 | H3: =LAUNCH_COST+CREW_TOOLKIT+VAN_PRICE -> 17000 | I3: =D3/FX-E3-F3-G3-H3 -> -17185.959 | J3: =I3 -> -17185.959 | L3: 7 | M3: =L3 -> 7 | N3: =L3*BLEND_PRICE_AMD -> 1281000 | O3: =FULL_ANNUAL_COST/12 -> 2242.8082 | P3: =IF(1>=MINI_HIRE_MONTH,MINI_ANNUAL_COST/12,0) -> 0 | Q3: =MKT_Y1+ADMIN_Y1 -> 450 | R3: =LAUNCH_COST+CREW_TOOLKIT+VAN_PRICE -> 17000 | S3: =N3/FX-O3-P3-Q3-R3 -> -16183.219 | T3: =S3 -> -16183.219 | V3: 9 | W3: =V3 -> 9 | X3: =V3*BLEND_PRICE_AMD -> 1647000 | Y3: =FULL_ANNUAL_COST/12 -> 2242.8082 | Z3: =IF(1>=MINI_HIRE_MONTH,MINI_ANNUAL_COST/12,0) -> 0 | AA3: =MKT_Y1+ADMIN_Y1 -> 450 | AB3: =LAUNCH_COST+CREW_TOOLKIT+VAN_PRICE -> 17000 | AC3: =X3/FX-Y3-Z3-AA3-AB3 -> -15180.479 | AD3: =AC3 -> -15180.479
A4: 2 | B4: 8 | C4: =C3+B4 -> 13 | D4: =B4*BLEND_PRICE_AMD -> 1464000 | E4: =FULL_ANNUAL_COST/12 -> 2242.8082 | F4: =IF(2>=MINI_HIRE_MONTH,MINI_ANNUAL_COST/12,0) -> 0 | G4: =MKT_Y1+ADMIN_Y1 -> 450 | H4: =IF(2=MINI_HIRE_MONTH,MINI_KIT,0) -> 0 | I4: =D4/FX-E4-F4-G4-H4 -> 1318.1507 | J4: =J3+I4 -> -15867.808 | L4: 11 | M4: =M3+L4 -> 18 | N4: =L4*BLEND_PRICE_AMD -> 2013000 | O4: =FULL_ANNUAL_COST/12 -> 2242.8082 | P4: =IF(2>=MINI_HIRE_MONTH,MINI_ANNUAL_COST/12,0) -> 0 | Q4: =MKT_Y1+ADMIN_Y1 -> 450 | R4: =IF(2=MINI_HIRE_MONTH,MINI_KIT,0) -> 0 | S4: =N4/FX-O4-P4-Q4-R4 -> 2822.2603 | T4: =T3+S4 -> -13360.959 | V4: 15 | W4: =W3+V4 -> 24 | X4: =V4*BLEND_PRICE_AMD -> 2745000 | Y4: =FULL_ANNUAL_COST/12 -> 2242.8082 | Z4: =IF(2>=MINI_HIRE_MONTH,MINI_ANNUAL_COST/12,0) -> 0 | AA4: =MKT_Y1+ADMIN_Y1 -> 450 | AB4: =IF(2=MINI_HIRE_MONTH,MINI_KIT,0) -> 0 | AC4: =X4/FX-Y4-Z4-AA4-AB4 -> 4827.7397 | AD4: =AD3+AC4 -> -10352.74
A5: 3 | B5: 11 | C5: =C4+B5 -> 24 | D5: =B5*BLEND_PRICE_AMD -> 2013000 | E5: =FULL_ANNUAL_COST/12 -> 2242.8082 | F5: =IF(3>=MINI_HIRE_MONTH,MINI_ANNUAL_COST/12,0) -> 0 | G5: =MKT_Y1+ADMIN_Y1 -> 450 | H5: =IF(3=MINI_HIRE_MONTH,MINI_KIT,0) -> 0 | I5: =D5/FX-E5-F5-G5-H5 -> 2822.2603 | J5: =J4+I5 -> -13045.548 | L5: 15 | M5: =M4+L5 -> 33 | N5: =L5*BLEND_PRICE_AMD -> 2745000 | O5: =FULL_ANNUAL_COST/12 -> 2242.8082 | P5: =IF(3>=MINI_HIRE_MONTH,MINI_ANNUAL_COST/12,0) -> 0 | Q5: =MKT_Y1+ADMIN_Y1 -> 450 | R5: =IF(3=MINI_HIRE_MONTH,MINI_KIT,0) -> 0 | S5: =N5/FX-O5-P5-Q5-R5 -> 4827.7397 | T5: =T4+S5 -> -8533.2192 | V5: 21 | W5: =W4+V5 -> 45 | X5: =V5*BLEND_PRICE_AMD -> 3843000 | Y5: =FULL_ANNUAL_COST/12 -> 2242.8082 | Z5: =IF(3>=MINI_HIRE_MONTH,MINI_ANNUAL_COST/12,0) -> 0 | AA5: =MKT_Y1+ADMIN_Y1 -> 450 | AB5: =IF(3=MINI_HIRE_MONTH,MINI_KIT,0) -> 0 | AC5: =X5/FX-Y5-Z5-AA5-AB5 -> 7835.9589 | AD5: =AD4+AC5 -> -2516.7808
A6: 4 | B6: 14 | C6: =C5+B6 -> 38 | D6: =B6*BLEND_PRICE_AMD -> 2562000 | E6: =FULL_ANNUAL_COST/12 -> 2242.8082 | F6: =IF(4>=MINI_HIRE_MONTH,MINI_ANNUAL_COST/12,0) -> 1001.7123 | G6: =MKT_Y1+ADMIN_Y1 -> 450 | H6: =IF(4=MINI_HIRE_MONTH,MINI_KIT,0) -> 250 | I6: =D6/FX-E6-F6-G6-H6 -> 3074.6575 | J6: =J5+I6 -> -9970.8904 | L6: 20 | M6: =M5+L6 -> 53 | N6: =L6*BLEND_PRICE_AMD -> 3660000 | O6: =FULL_ANNUAL_COST/12 -> 2242.8082 | P6: =IF(4>=MINI_HIRE_MONTH,MINI_ANNUAL_COST/12,0) -> 1001.7123 | Q6: =MKT_Y1+ADMIN_Y1 -> 450 | R6: =IF(4=MINI_HIRE_MONTH,MINI_KIT,0) -> 250 | S6: =N6/FX-O6-P6-Q6-R6 -> 6082.8767 | T6: =T5+S6 -> -2450.3425 | V6: 27 | W6: =W5+V6 -> 72 | X6: =V6*BLEND_PRICE_AMD -> 4941000 | Y6: =FULL_ANNUAL_COST/12 -> 2242.8082 | Z6: =IF(4>=MINI_HIRE_MONTH,MINI_ANNUAL_COST/12,0) -> 1001.7123 | AA6: =MKT_Y1+ADMIN_Y1 -> 450 | AB6: =IF(4=MINI_HIRE_MONTH,MINI_KIT,0) -> 250 | AC6: =X6/FX-Y6-Z6-AA6-AB6 -> 9592.4658 | AD6: =AD5+AC6 -> 7075.6849
A7: 5 | B7: 16 | C7: =C6+B7 -> 54 | D7: =B7*BLEND_PRICE_AMD -> 2928000 | E7: =FULL_ANNUAL_COST/12 -> 2242.8082 | F7: =IF(5>=MINI_HIRE_MONTH,MINI_ANNUAL_COST/12,0) -> 1001.7123 | G7: =MKT_Y1+ADMIN_Y1 -> 450 | H7: =IF(5=MINI_HIRE_MONTH,MINI_KIT,0) -> 0 | I7: =D7/FX-E7-F7-G7-H7 -> 4327.3973 | J7: =J6+I7 -> -5643.4932 | L7: 22 | M7: =M6+L7 -> 75 | N7: =L7*BLEND_PRICE_AMD -> 4026000 | O7: =FULL_ANNUAL_COST/12 -> 2242.8082 | P7: =IF(5>=MINI_HIRE_MONTH,MINI_ANNUAL_COST/12,0) -> 1001.7123 | Q7: =MKT_Y1+ADMIN_Y1 -> 450 | R7: =IF(5=MINI_HIRE_MONTH,MINI_KIT,0) -> 0 | S7: =N7/FX-O7-P7-Q7-R7 -> 7335.6164 | T7: =T6+S7 -> 4885.274 | V7: 30 | W7: =W6+V7 -> 102 | X7: =V7*BLEND_PRICE_AMD -> 5490000 | Y7: =FULL_ANNUAL_COST/12 -> 2242.8082 | Z7: =IF(5>=MINI_HIRE_MONTH,MINI_ANNUAL_COST/12,0) -> 1001.7123 | AA7: =MKT_Y1+ADMIN_Y1 -> 450 | AB7: =IF(5=MINI_HIRE_MONTH,MINI_KIT,0) -> 0 | AC7: =X7/FX-Y7-Z7-AA7-AB7 -> 11346.575 | AD7: =AD6+AC7 -> 18422.26
A8: 6 | B8: 16 | C8: =C7+B8 -> 70 | D8: =B8*BLEND_PRICE_AMD -> 2928000 | E8: =FULL_ANNUAL_COST/12 -> 2242.8082 | F8: =IF(6>=MINI_HIRE_MONTH,MINI_ANNUAL_COST/12,0) -> 1001.7123 | G8: =MKT_Y1+ADMIN_Y1 -> 450 | H8: =IF(6=MINI_HIRE_MONTH,MINI_KIT,0) -> 0 | I8: =D8/FX-E8-F8-G8-H8 -> 4327.3973 | J8: =J7+I8 -> -1316.0959 | L8: 22 | M8: =M7+L8 -> 97 | N8: =L8*BLEND_PRICE_AMD -> 4026000 | O8: =FULL_ANNUAL_COST/12 -> 2242.8082 | P8: =IF(6>=MINI_HIRE_MONTH,MINI_ANNUAL_COST/12,0) -> 1001.7123 | Q8: =MKT_Y1+ADMIN_Y1 -> 450 | R8: =IF(6=MINI_HIRE_MONTH,MINI_KIT,0) -> 0 | S8: =N8/FX-O8-P8-Q8-R8 -> 7335.6164 | T8: =T7+S8 -> 12220.89 | V8: 30 | W8: =W7+V8 -> 132 | X8: =V8*BLEND_PRICE_AMD -> 5490000 | Y8: =FULL_ANNUAL_COST/12 -> 2242.8082 | Z8: =IF(6>=MINI_HIRE_MONTH,MINI_ANNUAL_COST/12,0) -> 1001.7123 | AA8: =MKT_Y1+ADMIN_Y1 -> 450 | AB8: =IF(6=MINI_HIRE_MONTH,MINI_KIT,0) -> 0 | AC8: =X8/FX-Y8-Z8-AA8-AB8 -> 11346.575 | AD8: =AD7+AC8 -> 29768.836
A9: 7 | B9: 16 | C9: =C8+B9 -> 86 | D9: =B9*BLEND_PRICE_AMD -> 2928000 | E9: =FULL_ANNUAL_COST/12 -> 2242.8082 | F9: =IF(7>=MINI_HIRE_MONTH,MINI_ANNUAL_COST/12,0) -> 1001.7123 | G9: =MKT_Y1+ADMIN_Y1 -> 450 | H9: =IF(7=MINI_HIRE_MONTH,MINI_KIT,0) -> 0 | I9: =D9/FX-E9-F9-G9-H9 -> 4327.3973 | J9: =J8+I9 -> 3011.3014 | L9: 22 | M9: =M8+L9 -> 119 | N9: =L9*BLEND_PRICE_AMD -> 4026000 | O9: =FULL_ANNUAL_COST/12 -> 2242.8082 | P9: =IF(7>=MINI_HIRE_MONTH,MINI_ANNUAL_COST/12,0) -> 1001.7123 | Q9: =MKT_Y1+ADMIN_Y1 -> 450 | R9: =IF(7=MINI_HIRE_MONTH,MINI_KIT,0) -> 0 | S9: =N9/FX-O9-P9-Q9-R9 -> 7335.6164 | T9: =T8+S9 -> 19556.507 | V9: 30 | W9: =W8+V9 -> 162 | X9: =V9*BLEND_PRICE_AMD -> 5490000 | Y9: =FULL_ANNUAL_COST/12 -> 2242.8082 | Z9: =IF(7>=MINI_HIRE_MONTH,MINI_ANNUAL_COST/12,0) -> 1001.7123 | AA9: =MKT_Y1+ADMIN_Y1 -> 450 | AB9: =IF(7=MINI_HIRE_MONTH,MINI_KIT,0) -> 0 | AC9: =X9/FX-Y9-Z9-AA9-AB9 -> 11346.575 | AD9: =AD8+AC9 -> 41115.411
A10: 8 | B10: 16 | C10: =C9+B10 -> 102 | D10: =B10*BLEND_PRICE_AMD -> 2928000 | E10: =FULL_ANNUAL_COST/12 -> 2242.8082 | F10: =IF(8>=MINI_HIRE_MONTH,MINI_ANNUAL_COST/12,0) -> 1001.7123 | G10: =MKT_Y1+ADMIN_Y1 -> 450 | H10: =IF(8=MINI_HIRE_MONTH,MINI_KIT,0) -> 0 | I10: =D10/FX-E10-F10-G10-H10 -> 4327.3973 | J10: =J9+I10 -> 7338.6986 | L10: 22 | M10: =M9+L10 -> 141 | N10: =L10*BLEND_PRICE_AMD -> 4026000 | O10: =FULL_ANNUAL_COST/12 -> 2242.8082 | P10: =IF(8>=MINI_HIRE_MONTH,MINI_ANNUAL_COST/12,0) -> 1001.7123 | Q10: =MKT_Y1+ADMIN_Y1 -> 450 | R10: =IF(8=MINI_HIRE_MONTH,MINI_KIT,0) -> 0 | S10: =N10/FX-O10-P10-Q10-R10 -> 7335.6164 | T10: =T9+S10 -> 26892.123 | V10: 30 | W10: =W9+V10 -> 192 | X10: =V10*BLEND_PRICE_AMD -> 5490000 | Y10: =FULL_ANNUAL_COST/12 -> 2242.8082 | Z10: =IF(8>=MINI_HIRE_MONTH,MINI_ANNUAL_COST/12,0) -> 1001.7123 | AA10: =MKT_Y1+ADMIN_Y1 -> 450 | AB10: =IF(8=MINI_HIRE_MONTH,MINI_KIT,0) -> 0 | AC10: =X10/FX-Y10-Z10-AA10-AB10 -> 11346.575 | AD10: =AD9+AC10 -> 52461.986
A11: 9 | B11: 14 | C11: =C10+B11 -> 116 | D11: =B11*BLEND_PRICE_AMD -> 2562000 | E11: =FULL_ANNUAL_COST/12 -> 2242.8082 | F11: =IF(9>=MINI_HIRE_MONTH,MINI_ANNUAL_COST/12,0) -> 1001.7123 | G11: =MKT_Y1+ADMIN_Y1 -> 450 | H11: =IF(9=MINI_HIRE_MONTH,MINI_KIT,0) -> 0 | I11: =D11/FX-E11-F11-G11-H11 -> 3324.6575 | J11: =J10+I11 -> 10663.356 | L11: 20 | M11: =M10+L11 -> 161 | N11: =L11*BLEND_PRICE_AMD -> 3660000 | O11: =FULL_ANNUAL_COST/12 -> 2242.8082 | P11: =IF(9>=MINI_HIRE_MONTH,MINI_ANNUAL_COST/12,0) -> 1001.7123 | Q11: =MKT_Y1+ADMIN_Y1 -> 450 | R11: =IF(9=MINI_HIRE_MONTH,MINI_KIT,0) -> 0 | S11: =N11/FX-O11-P11-Q11-R11 -> 6332.8767 | T11: =T10+S11 -> 33225 | V11: 27 | W11: =W10+V11 -> 219 | X11: =V11*BLEND_PRICE_AMD -> 4941000 | Y11: =FULL_ANNUAL_COST/12 -> 2242.8082 | Z11: =IF(9>=MINI_HIRE_MONTH,MINI_ANNUAL_COST/12,0) -> 1001.7123 | AA11: =MKT_Y1+ADMIN_Y1 -> 450 | AB11: =IF(9=MINI_HIRE_MONTH,MINI_KIT,0) -> 0 | AC11: =X11/FX-Y11-Z11-AA11-AB11 -> 9842.4658 | AD11: =AD10+AC11 -> 62304.452
A12: 10 | B12: 14 | C12: =C11+B12 -> 130 | D12: =B12*BLEND_PRICE_AMD -> 2562000 | E12: =FULL_ANNUAL_COST/12 -> 2242.8082 | F12: =IF(10>=MINI_HIRE_MONTH,MINI_ANNUAL_COST/12,0) -> 1001.7123 | G12: =MKT_Y1+ADMIN_Y1 -> 450 | H12: =IF(10=MINI_HIRE_MONTH,MINI_KIT,0) -> 0 | I12: =D12/FX-E12-F12-G12-H12 -> 3324.6575 | J12: =J11+I12 -> 13988.014 | L12: 20 | M12: =M11+L12 -> 181 | N12: =L12*BLEND_PRICE_AMD -> 3660000 | O12: =FULL_ANNUAL_COST/12 -> 2242.8082 | P12: =IF(10>=MINI_HIRE_MONTH,MINI_ANNUAL_COST/12,0) -> 1001.7123 | Q12: =MKT_Y1+ADMIN_Y1 -> 450 | R12: =IF(10=MINI_HIRE_MONTH,MINI_KIT,0) -> 0 | S12: =N12/FX-O12-P12-Q12-R12 -> 6332.8767 | T12: =T11+S12 -> 39557.877 | V12: 27 | W12: =W11+V12 -> 246 | X12: =V12*BLEND_PRICE_AMD -> 4941000 | Y12: =FULL_ANNUAL_COST/12 -> 2242.8082 | Z12: =IF(10>=MINI_HIRE_MONTH,MINI_ANNUAL_COST/12,0) -> 1001.7123 | AA12: =MKT_Y1+ADMIN_Y1 -> 450 | AB12: =IF(10=MINI_HIRE_MONTH,MINI_KIT,0) -> 0 | AC12: =X12/FX-Y12-Z12-AA12-AB12 -> 9842.4658 | AD12: =AD11+AC12 -> 72146.918
A13: 11 | B13: 15 | C13: =C12+B13 -> 145 | D13: =B13*BLEND_PRICE_AMD -> 2745000 | E13: =FULL_ANNUAL_COST/12 -> 2242.8082 | F13: =IF(11>=MINI_HIRE_MONTH,MINI_ANNUAL_COST/12,0) -> 1001.7123 | G13: =MKT_Y1+ADMIN_Y1 -> 450 | H13: =IF(11=MINI_HIRE_MONTH,MINI_KIT,0) -> 0 | I13: =D13/FX-E13-F13-G13-H13 -> 3826.0274 | J13: =J12+I13 -> 17814.041 | L13: 20 | M13: =M12+L13 -> 201 | N13: =L13*BLEND_PRICE_AMD -> 3660000 | O13: =FULL_ANNUAL_COST/12 -> 2242.8082 | P13: =IF(11>=MINI_HIRE_MONTH,MINI_ANNUAL_COST/12,0) -> 1001.7123 | Q13: =MKT_Y1+ADMIN_Y1 -> 450 | R13: =IF(11=MINI_HIRE_MONTH,MINI_KIT,0) -> 0 | S13: =N13/FX-O13-P13-Q13-R13 -> 6332.8767 | T13: =T12+S13 -> 45890.753 | V13: 27 | W13: =W12+V13 -> 273 | X13: =V13*BLEND_PRICE_AMD -> 4941000 | Y13: =FULL_ANNUAL_COST/12 -> 2242.8082 | Z13: =IF(11>=MINI_HIRE_MONTH,MINI_ANNUAL_COST/12,0) -> 1001.7123 | AA13: =MKT_Y1+ADMIN_Y1 -> 450 | AB13: =IF(11=MINI_HIRE_MONTH,MINI_KIT,0) -> 0 | AC13: =X13/FX-Y13-Z13-AA13-AB13 -> 9842.4658 | AD13: =AD12+AC13 -> 81989.384
A14: 12 | B14: 15 | C14: =C13+B14 -> 160 | D14: =B14*BLEND_PRICE_AMD -> 2745000 | E14: =FULL_ANNUAL_COST/12 -> 2242.8082 | F14: =IF(12>=MINI_HIRE_MONTH,MINI_ANNUAL_COST/12,0) -> 1001.7123 | G14: =MKT_Y1+ADMIN_Y1 -> 450 | H14: =IF(12=MINI_HIRE_MONTH,MINI_KIT,0) -> 0 | I14: =D14/FX-E14-F14-G14-H14 -> 3826.0274 | J14: =J13+I14 -> 21640.068 | L14: 19 | M14: =M13+L14 -> 220 | N14: =L14*BLEND_PRICE_AMD -> 3477000 | O14: =FULL_ANNUAL_COST/12 -> 2242.8082 | P14: =IF(12>=MINI_HIRE_MONTH,MINI_ANNUAL_COST/12,0) -> 1001.7123 | Q14: =MKT_Y1+ADMIN_Y1 -> 450 | R14: =IF(12=MINI_HIRE_MONTH,MINI_KIT,0) -> 0 | S14: =N14/FX-O14-P14-Q14-R14 -> 5831.5068 | T14: =T13+S14 -> 51722.26 | V14: 27 | W14: =W13+V14 -> 300 | X14: =V14*BLEND_PRICE_AMD -> 4941000 | Y14: =FULL_ANNUAL_COST/12 -> 2242.8082 | Z14: =IF(12>=MINI_HIRE_MONTH,MINI_ANNUAL_COST/12,0) -> 1001.7123 | AA14: =MKT_Y1+ADMIN_Y1 -> 450 | AB14: =IF(12=MINI_HIRE_MONTH,MINI_KIT,0) -> 0 | AC14: =X14/FX-Y14-Z14-AA14-AB14 -> 9842.4658 | AD14: =AD13+AC14 -> 91831.849
A15: Итог/год | B15: =SUM(B3:B14) -> 160 | C15: =C14 -> 160 | D15: =SUM(D3:D14) -> 29280000 | E15: =SUM(E3:E14) -> 26913.699 | F15: =SUM(F3:F14) -> 9015.411 | G15: =SUM(G3:G14) -> 5400 | H15: =SUM(H3:H14) -> 17250 | I15: =SUM(I3:I14) -> 21640.068 | J15: =J14 -> 21640.068 | L15: =SUM(L3:L14) -> 220 | M15: =M14 -> 220 | N15: =SUM(N3:N14) -> 40260000 | O15: =SUM(O3:O14) -> 26913.699 | P15: =SUM(P3:P14) -> 9015.411 | Q15: =SUM(Q3:Q14) -> 5400 | R15: =SUM(R3:R14) -> 17250 | S15: =SUM(S3:S14) -> 51722.26 | T15: =T14 -> 51722.26 | V15: =SUM(V3:V14) -> 300 | W15: =W14 -> 300 | X15: =SUM(X3:X14) -> 54900000 | Y15: =SUM(Y3:Y14) -> 26913.699 | Z15: =SUM(Z3:Z14) -> 9015.411 | AA15: =SUM(AA3:AA14) -> 5400 | AB15: =SUM(AB3:AB14) -> 17250 | AC15: =SUM(AC3:AC14) -> 91831.849 | AD15: =AD14 -> 91831.849
A16: Мин. накопл. кэш (пик потребности) | J16: =MIN(J3:J14) -> -17185.959 | T16: =MIN(T3:T14) -> -16183.219 | AD16: =MIN(AD3:AD14) -> -15180.479
A17: Проверка: сумма новых = цель сценария | B17: =B15-TARGET_WORST -> 0 | L17: =L15-TARGET_NORMAL -> 0 | V17: =V15-TARGET_POSITIVE -> 0

Sheet 5-Year P&L
A1: 5-Year P&L — три сценария Года 1, единая траектория роста Год 2-5 (45%/30%/20%/15%)
A3: СЦЕНАРИЙ: ХУДШИЙ — 160 КЛИЕНТОВ
B4: Year 1 | C4: Year 2 | D4: Year 3 | E4: Year 4 | F4: Year 5
A5: Тяжёлых экипажей (#) | B5: 1 | C5: 1 | D5: 1 | E5: 1 | F5: 1
A6: Мини-визитёров (#) | B6: 1 | C6: 1 | D6: 1 | E6: 1 | F6: 1
A7: Кластеризация активна? (1/0) | B7: 0 | C7: 0 | D7: 0 | E7: 0 | F7: 0
A8: Мощность (потолок клиентов, конфигурация года) | B8: =MIN(B5*IF(B7=1,'Capacity Model'!$B$14,'Capacity Model'!$B$13)/BLEND_HVISITS,B6*IF(B7=1,'Capacity Model'!$B$16,'Capacity Model'!$B$15)/BLEND_LVISITS) -> 610.43478 | C8: =MIN(C5*IF(C7=1,'Capacity Model'!$B$14,'Capacity Model'!$B$13)/BLEND_HVISITS,C6*IF(C7=1,'Capacity Model'!$B$16,'Capacity Model'!$B$15)/BLEND_LVISITS) -> 610.43478 | D8: =MIN(D5*IF(D7=1,'Capacity Model'!$B$14,'Capacity Model'!$B$13)/BLEND_HVISITS,D6*IF(D7=1,'Capacity Model'!$B$16,'Capacity Model'!$B$15)/BLEND_LVISITS) -> 610.43478 | E8: =MIN(E5*IF(E7=1,'Capacity Model'!$B$14,'Capacity Model'!$B$13)/BLEND_HVISITS,E6*IF(E7=1,'Capacity Model'!$B$16,'Capacity Model'!$B$15)/BLEND_LVISITS) -> 610.43478 | F8: =MIN(F5*IF(F7=1,'Capacity Model'!$B$14,'Capacity Model'!$B$13)/BLEND_HVISITS,F6*IF(F7=1,'Capacity Model'!$B$16,'Capacity Model'!$B$15)/BLEND_LVISITS) -> 610.43478
A9: Клиенты — начало года | B9: 0 | C9: =B11 -> 160 | D9: =C11 -> 232 | E9: =D11 -> 301.6 | F9: =E11 -> 361.92
A10: Продлевающие клиенты (start x (1-churn)) | B10: 0 | C10: =C9*(1-CHURN_RATE) -> 136 | D10: =D9*(1-CHURN_RATE) -> 197.2 | E10: =E9*(1-CHURN_RATE) -> 256.36 | F10: =F9*(1-CHURN_RATE) -> 307.632
A11: Клиенты — конец года (цель, капед по мощности) | B11: =Y1_EOY_CLIENTS_Worst -> 160 | C11: =MIN(C9*(1+GROWTH_Y2),C8) -> 232 | D11: =MIN(D9*(1+GROWTH_Y3),D8) -> 301.6 | E11: =MIN(E9*(1+GROWTH_Y4),E8) -> 361.92 | F11: =MIN(F9*(1+GROWTH_Y5),F8) -> 416.208
A12: Новых подписок нужно за год | B12: =B11 -> 160 | C12: =C11-C10 -> 96 | D12: =D11-D10 -> 104.4 | E12: =E11-E10 -> 105.56 | F12: =F11-F10 -> 108.576
A13: Потеряно из-за оттока | B13: 0 | C13: =C9*CHURN_RATE -> 24 | D13: =D9*CHURN_RATE -> 34.8 | E13: =E9*CHURN_RATE -> 45.24 | F13: =F9*CHURN_RATE -> 54.288
A14: Клиенты — среднее за год | B14: =AVERAGE('Y1 Monthly Build'!C3:C14) -> 78.583333 | C14: =(C9+C11)/2 -> 196 | D14: =(D9+D11)/2 -> 266.8 | E14: =(E9+E11)/2 -> 331.76 | F14: =(F9+F11)/2 -> 389.064
A15: Утилизация мощности (EOY/потолок) | B15: =B11/B8 -> 0.26210826 | C15: =C11/C8 -> 0.38005698 | D15: =D11/D8 -> 0.49407407 | E15: =E11/E8 -> 0.59288889 | F15: =F11/F8 -> 0.68182222
A17: ВЫРУЧКА И НАЛОГ ($)
A19: Выручка (EOY клиенты x blended price) | B19: =B11*BLEND_PRICE_AMD/FX -> 80219.178 | C19: =C11*BLEND_PRICE_AMD/FX -> 116317.81 | D19: =D11*BLEND_PRICE_AMD/FX -> 151213.15 | E19: =E11*BLEND_PRICE_AMD/FX -> 181455.78 | F19: =F11*BLEND_PRICE_AMD/FX -> 208674.15
A20: Налог с оборота (10%) | B20: =B19*TAX_RATE -> 8021.9178 | C20: =C19*TAX_RATE -> 11631.781 | D20: =D19*TAX_RATE -> 15121.315 | E20: =E19*TAX_RATE -> 18145.578 | F20: =F19*TAX_RATE -> 20867.415
A21: Выручка после налога | B21: =B19-B20 -> 72197.26 | C21: =C19-C20 -> 104686.03 | D21: =D19-D20 -> 136091.84 | E21: =E19-E20 -> 163310.2 | F21: =F19-F20 -> 187806.73
A23: ОПЕРАЦИОННЫЕ РАСХОДЫ ($)
A25: Тяж. экипажи (зарплаты+авто) | B25: =Y1_CREW_COST_Worst -> 26913.699 | C25: =C5*FULL_ANNUAL_COST -> 26913.699 | D25: =D5*FULL_ANNUAL_COST -> 26913.699 | E25: =E5*FULL_ANNUAL_COST -> 26913.699 | F25: =F5*FULL_ANNUAL_COST -> 26913.699
A26: Мини-визитёры | B26: =Y1_MINI_COST_Worst -> 9015.411 | C26: =C6*MINI_ANNUAL_COST -> 12020.548 | D26: =D6*MINI_ANNUAL_COST -> 12020.548 | E26: =E6*MINI_ANNUAL_COST -> 12020.548 | F26: =F6*MINI_ANNUAL_COST -> 12020.548
A27: Маркетинг + админ | B27: =Y1_MKT_COST_Worst -> 5400 | C27: =(MKT_Y1+MKT_GROWTH*1+ADMIN_Y1+ADMIN_GROWTH*1)*12 -> 7200 | D27: =(MKT_Y1+MKT_GROWTH*2+ADMIN_Y1+ADMIN_GROWTH*2)*12 -> 9000 | E27: =(MKT_Y1+MKT_GROWTH*3+ADMIN_Y1+ADMIN_GROWTH*3)*12 -> 10800 | F27: =(MKT_Y1+MKT_GROWTH*4+ADMIN_Y1+ADMIN_GROWTH*4)*12 -> 12600
A28: ИТОГО операционные расходы | B28: =B25+B26+B27 -> 41329.11 | C28: =C25+C26+C27 -> 46134.247 | D28: =D25+D26+D27 -> 47934.247 | E28: =E25+E26+E27 -> 49734.247 | F28: =F25+F26+F27 -> 51534.247
A30: EBITDA
A32: EBITDA | B32: =B21-B28 -> 30868.151 | C32: =C21-C28 -> 58551.781 | D32: =D21-D28 -> 88157.589 | E32: =E21-E28 -> 113575.96 | F32: =F21-F28 -> 136272.49
A33: EBITDA маржа, % | B33: =B32/B21 -> 0.42755294 | C33: =C32/C21 -> 0.55930846 | D33: =D32/D21 -> 0.64778015 | E33: =E32/E21 -> 0.69546149 | F33: =F32/F21 -> 0.72559958
A35: КАПЕКС И ДЕНЕЖНЫЙ ПОТОК ($)
A37: Новых экипажей добавлено | B37: 1 | C37: =C5-B5 -> 0 | D37: =D5-C5 -> 0 | E37: =E5-D5 -> 0 | F37: =F5-E5 -> 0
A38: Новых визитёров добавлено | B38: 1 | C38: =C6-B6 -> 0 | D38: =D6-C6 -> 0 | E38: =E6-D6 -> 0 | F38: =F6-E6 -> 0
A39: Капекс (новый экипаж/визитёр + запуск Год1) | B39: =Y1_CAPEX_Worst -> 17250 | C39: =C37*(VAN_PRICE+CREW_TOOLKIT)+C38*MINI_KIT -> 0 | D39: =D37*(VAN_PRICE+CREW_TOOLKIT)+D38*MINI_KIT -> 0 | E39: =E37*(VAN_PRICE+CREW_TOOLKIT)+E38*MINI_KIT -> 0 | F39: =F37*(VAN_PRICE+CREW_TOOLKIT)+F38*MINI_KIT -> 0
A40: Чистый денежный поток (EBITDA - Капекс) | B40: =B32-B39 -> 13618.151 | C40: =C32-C39 -> 58551.781 | D40: =D32-D39 -> 88157.589 | E40: =E32-E39 -> 113575.96 | F40: =F32-F39 -> 136272.49
A41: Накопленный кэш (до внешнего финансирования) | B41: =B40 -> 13618.151 | C41: =B41+C40 -> 72169.932 | D41: =C41+D40 -> 160327.52 | E41: =D41+E40 -> 273903.48 | F41: =E41+F40 -> 410175.96
A44: СЦЕНАРИЙ: НОРМАЛЬНЫЙ — 220 КЛИЕНТОВ
B45: Year 1 | C45: Year 2 | D45: Year 3 | E45: Year 4 | F45: Year 5
A46: Тяжёлых экипажей (#) | B46: 1 | C46: 1 | D46: 1 | E46: 1 | F46: 1
A47: Мини-визитёров (#) | B47: 1 | C47: 1 | D47: 1 | E47: 1 | F47: 1
A48: Кластеризация активна? (1/0) | B48: 0 | C48: 0 | D48: 0 | E48: 0 | F48: 0
A49: Мощность (потолок клиентов, конфигурация года) | B49: =MIN(B46*IF(B48=1,'Capacity Model'!$B$14,'Capacity Model'!$B$13)/BLEND_HVISITS,B47*IF(B48=1,'Capacity Model'!$B$16,'Capacity Model'!$B$15)/BLEND_LVISITS) -> 610.43478 | C49: =MIN(C46*IF(C48=1,'Capacity Model'!$B$14,'Capacity Model'!$B$13)/BLEND_HVISITS,C47*IF(C48=1,'Capacity Model'!$B$16,'Capacity Model'!$B$15)/BLEND_LVISITS) -> 610.43478 | D49: =MIN(D46*IF(D48=1,'Capacity Model'!$B$14,'Capacity Model'!$B$13)/BLEND_HVISITS,D47*IF(D48=1,'Capacity Model'!$B$16,'Capacity Model'!$B$15)/BLEND_LVISITS) -> 610.43478 | E49: =MIN(E46*IF(E48=1,'Capacity Model'!$B$14,'Capacity Model'!$B$13)/BLEND_HVISITS,E47*IF(E48=1,'Capacity Model'!$B$16,'Capacity Model'!$B$15)/BLEND_LVISITS) -> 610.43478 | F49: =MIN(F46*IF(F48=1,'Capacity Model'!$B$14,'Capacity Model'!$B$13)/BLEND_HVISITS,F47*IF(F48=1,'Capacity Model'!$B$16,'Capacity Model'!$B$15)/BLEND_LVISITS) -> 610.43478
A50: Клиенты — начало года | B50: 0 | C50: =B52 -> 220 | D50: =C52 -> 319 | E50: =D52 -> 414.7 | F50: =E52 -> 497.64
A51: Продлевающие клиенты (start x (1-churn)) | B51: 0 | C51: =C50*(1-CHURN_RATE) -> 187 | D51: =D50*(1-CHURN_RATE) -> 271.15 | E51: =E50*(1-CHURN_RATE) -> 352.495 | F51: =F50*(1-CHURN_RATE) -> 422.994
...

Sheet Funding Summary
A1: Funding Ask — сравнение сценариев для Давида
B3: Худший — 160 клиентов | C3: Нормальный — 220 клиентов | D3: Позитивный — 300 клиентов
A4: Клиенты, конец Года 1 | B4: =Y1_EOY_CLIENTS_Worst -> 160 | C4: =Y1_EOY_CLIENTS_Normal -> 220 | D4: =Y1_EOY_CLIENTS_Positive -> 300
A5: Выручка Год 1, после налога, $ | B5: =PNL_Worst_REV_Y1 -> 72197.26 | C5: =PNL_Normal_REV_Y1 -> 99271.233 | D5: =PNL_Positive_REV_Y1 -> 135369.86
A6: EBITDA Год 1, $ | B6: =PNL_Worst_EBITDA_Y1 -> 30868.151 | C6: =PNL_Normal_EBITDA_Y1 -> 57942.123 | D6: =PNL_Positive_EBITDA_Y1 -> 94040.753
A7: Капекс Год 1, $ | B7: =Y1_CAPEX_Worst -> 17250 | C7: =Y1_CAPEX_Normal -> 17250 | D7: =Y1_CAPEX_Positive -> 17250
A8: Мин. накопленный кэш в течение Года 1 (пик потребности), $ | B8: =Y1_PEAKCASH_Worst -> -17185.959 | C8: =Y1_PEAKCASH_Normal -> -16183.219 | D8: =Y1_PEAKCASH_Positive -> -15180.479
A9: Рекомендуемый ask у Давида (|пик| x 1.15 буфер), $ | B9: =-MIN(0,B8)*1.15 -> 19763.853 | C9: =-MIN(0,C8)*1.15 -> 18610.702 | D9: =-MIN(0,D8)*1.15 -> 17457.551
A11: 5-ЛЕТНИЙ ВЗГЛЯД — EBITDA ($) ПО СЦЕНАРИЯМ
B13: Y1 | C13: Y2 | D13: Y3 | E13: Y4 | F13: Y5
A14: Худший — 160 клиентов | B14: =PNL_Worst_EBITDA_Y1 -> 30868.151 | C14: =PNL_Worst_EBITDA_Y2 -> 58551.781 | D14: =PNL_Worst_EBITDA_Y3 -> 88157.589 | E14: =PNL_Worst_EBITDA_Y4 -> 113575.96 | F14: =PNL_Worst_EBITDA_Y5 -> 136272.49
A15: Нормальный — 220 клиентов | B15: =PNL_Normal_EBITDA_Y1 -> 57942.123 | C15: =PNL_Normal_EBITDA_Y2 -> 97809.041 | D15: =PNL_Normal_EBITDA_Y3 -> 139192.03 | E15: =PNL_Normal_EBITDA_Y4 -> 174817.28 | F15: =PNL_Normal_EBITDA_Y5 -> 206700.01
A16: Позитивный — 300 клиентов | B16: =PNL_Positive_EBITDA_Y1 -> 94040.753 | C16: =PNL_Positive_EBITDA_Y2 -> 150152.05 | D16: =PNL_Positive_EBITDA_Y3 -> 207237.95 | E16: =PNL_Positive_EBITDA_Y4 -> 244451.84 | F16: =PNL_Positive_EBITDA_Y5 -> 261669.13
A18: 5-ЛЕТНИЙ ВЗГЛЯД — КЛИЕНТЫ (EOY) ПО СЦЕНАРИЯМ
B20: Y1 | C20: Y2 | D20: Y3 | E20: Y4 | F20: Y5
A21: Худший — 160 клиентов | B21: =PNL_Worst_CLIENTS_Y1 -> 160 | C21: =PNL_Worst_CLIENTS_Y2 -> 232 | D21: =PNL_Worst_CLIENTS_Y3 -> 301.6 | E21: =PNL_Worst_CLIENTS_Y4 -> 361.92 | F21: =PNL_Worst_CLIENTS_Y5 -> 416.208
A22: Нормальный — 220 клиентов | B22: =PNL_Normal_CLIENTS_Y1 -> 220 | C22: =PNL_Normal_CLIENTS_Y2 -> 319 | D22: =PNL_Normal_CLIENTS_Y3 -> 414.7 | E22: =PNL_Normal_CLIENTS_Y4 -> 497.64 | F22: =PNL_Normal_CLIENTS_Y5 -> 572.286
A23: Позитивный — 300 клиентов | B23: =PNL_Positive_CLIENTS_Y1 -> 300 | C23: =PNL_Positive_CLIENTS_Y2 -> 435 | D23: =PNL_Positive_CLIENTS_Y3 -> 565.5 | E23: =PNL_Positive_CLIENTS_Y4 -> 678.6 | F23: =PNL_Positive_CLIENTS_Y5 -> 780.39
A25: Примечание: капекс Года 1 одинаков во всех сценариях (1 экипаж + запуск + мини-визитёр в Месяце 4) —
A26: разница в ask объясняется исключительно скоростью прихода выручки от новых клиентов, а не расходами.
